Traceback (most recent call last):
  File "/opt/anaconda3/lib/python3.8/site-packages/jupyter_cache/executors/utils.py", line 51, in single_nb_execution
    executenb(
  File "/opt/anaconda3/lib/python3.8/site-packages/nbclient/client.py", line 1112, in execute
    return NotebookClient(nb=nb, resources=resources, km=km, **kwargs).execute()
  File "/opt/anaconda3/lib/python3.8/site-packages/nbclient/util.py", line 74, in wrapped
    return just_run(coro(*args, **kwargs))
  File "/opt/anaconda3/lib/python3.8/site-packages/nbclient/util.py", line 53, in just_run
    return loop.run_until_complete(coro)
  File "/opt/anaconda3/lib/python3.8/asyncio/base_events.py", line 616, in run_until_complete
    return future.result()
  File "/opt/anaconda3/lib/python3.8/site-packages/nbclient/client.py", line 553, in async_execute
    await self.async_execute_cell(
  File "/opt/anaconda3/lib/python3.8/site-packages/nbclient/client.py", line 857, in async_execute_cell
    self._check_raise_for_error(cell, exec_reply)
  File "/opt/anaconda3/lib/python3.8/site-packages/nbclient/client.py", line 760, in _check_raise_for_error
    raise CellExecutionError.from_cell_and_msg(cell, exec_reply_content)
nbclient.exceptions.CellExecutionError: An error occurred while executing the following cell:
------------------
# Mauvaise indentation!
if Instruction1:
    if Instruction2:
    print("l'Instruction1 et l'Instruction2 sont toutes les deux True")  # Cette ligne n'est pas correctement indent√©e
------------------

[0;36m  File [0;32m"/var/folders/2b/cj2pm60x61s5qlxpmr7g7km00000gn/T/ipykernel_6795/510671156.py"[0;36m, line [0;32m4[0m
[0;31m    print("l'Instruction1 et l'Instruction2 sont toutes les deux True")  # Cette ligne n'est pas correctement indent√©e[0m
[0m    ^[0m
[0;31mIndentationError[0m[0;31m:[0m expected an indented block

IndentationError: expected an indented block (510671156.py, line 4)

